Workbook
Name \0: #REF!
Name \0: #REF!
Name \0: #REF!
Name \A: #REF!
Name \A: #REF!
Name \A: #REF!
Name \b: #REF!
Name \b: #REF!
Name \D: #REF!
Name \D: #REF!
Name \F: #REF!
Name \F: #REF!
Name \G: #REF!
Name \G: #REF!
Name \H: #REF!
Name \H: #REF!
Name \I: #REF!
Name \I: #REF!
Name \J: #REF!
Name \J: #REF!
Name \K: #REF!
Name \K: #REF!
Name \L: #REF!
Name \L: #REF!
Name \M: #REF!
Name \M: #REF!
Name \N: #REF!
Name \N: #REF!
Name \P: #REF!
Name \P: #REF!
Name \R: #REF!
Name \R: #REF!
Name \U: #REF!
Name \U: #REF!
Name \W: #REF!
Name \W: #REF!
Name _: #REF!
Name _: #REF!
Name __: #REF!
Name __: #REF!
Name ___: #REF!
Name ___: #REF!
Name ____: #REF!
Name ____: #REF!
Name _____: #REF!
Name _____: #REF!
Name ______: #REF!
Name ______: #REF!
Name _______: #REF!
Name _______: #REF!
Name ________: #REF!
Name ________: #REF!
Name _________: #REF!
Name _________: #REF!
Name __________: #REF!
Name __________: #REF!
Name ___________: #REF!
Name ___________: #REF!
Name ____________: #REF!
Name ____________: #REF!

Sheet P&L
E1: 50/20/20/10
A2: Project #:
E3: 0.5 | F3: 0.2 | G3: 0.2 | H3: 0.1
B4: PROJECTS BUDGET | I4: CONTRACT BUDGET - WARRANTY,SERVICE TAX INCL.
B6: Revenue | C6: Budgeted Cost | D6: Margin | I6: Revenue | J6: Budgeted Cost | K6: Margin
A7: Base Contract | B7: =B36 -> 0 | C7: =C36 -> 0 | D7: =B7-C7 -> 0 | H7: TOTAL BASE CONTRACT | I7: 175000 | J7: 101127.02 | K7: =I7-J7 -> 73872.98
A8: TOTAL BASE CONTRACT | B8: =SUM(B7:B7) -> 0 | C8: =SUM(C7:C7) -> 0 | D8: =SUM(D7:D7) -> 0 | I8: CHANGE ORDERS
I9: Revenue | J9: Budgeted Cost | K9: Margin
B10: Revenue | C10: Budgeted Cost | D10: Margin | H10: Total Change Order(s) Amount | I10: =D42 -> 0 | J10: =E42 -> 0 | K10: =I10-J10 -> 0
A11: Change Orders | B11: =B42 -> 0 | C11: =C42 -> 0 | D11: =B11-C11 -> 0 | I11: REVISED CONTRACT TOTAL
A12: Total Change Order(s) Amount | B12: =SUM(B11:B11) -> 0 | C12: =SUM(C11:C11) -> 0 | D12: =B12-C12 -> 0 | H12: Grand Total | I12: =I7+I10 -> 175000 | J12: =J7+J10 -> 101127.02 | K12: =I12-J12 -> 73872.98
A14: Grand Total | B14: =SUM(B8+B12) -> 0 | C14: =SUM(C8+C12) -> 0 | D14: =B14-C14 -> 0 | I14: Revenue | J14: Actual Cost | K14: Margin
H15: Margin Tracking | I15: =I12 -> 175000 | J15: =J12 -> 101127.02 | K15: =I15-J15 -> 73872.98
B16: Revenue | C16: Actual Cost | D16: Margin
A17: Margin Tracking | B17: =B14 -> 0 | C17: =SUM(D44:E44) -> 0 | D17: =B17-C17 -> 0
B18: =SUM(B17:B17) -> 0 | C18: =SUM(C17:C17) -> 0 | D18: =B18-C18 -> 0 | I18: Services/Warranty | J18: Revenue | K18: Budgeted Cost
I19: Advertising
I20: Parts/Labor | J20: 23707 | K20: 13750
I21: Graphics/Design
A22: Cost Category | B22: Revenue | C22: Budget | D22: Committed POs | E22: Budget Remaining | I22: Software License | J22: ='[298]Cost Summary'!L97 -> 0
A23: LED | B23: 0 | C23: 0 | D23: =SUMIF('PO''s '!$E$2:E112,'P&L'!A23,'PO''s '!$D$2:D112) -> 167523 | E23: =SUM(C23-D23) -> -167523 | I23: Tax
A24: Install | B24: 0 | C24: 0 | D24: =SUMIF('PO''s '!$E$2:E113,'P&L'!A24,'PO''s '!$D$2:D113) -> 94724 | E24: =SUM(C24-D24) -> -94724 | I24: Total | J24: =SUM(J19:J23) -> 23707 | K24: =SUM(K19:K23) -> 13750
A25: Electrical | B25: 0 | C25: 0 | D25: =SUMIF('PO''s '!$E$2:E114,'P&L'!A25,'PO''s '!$D$2:D114) -> 0 | E25: =SUM(C25-D25) -> 0
A26: ANC Travel | B26: 0 | C26: 0 | D26: =SUMIF('PO''s '!$E$2:E115,'P&L'!A26,'PO''s '!$D$2:D115) -> 0 | E26: =SUM(C26-D26) -> 0
A27: Structural Engineering | B27: 0 | C27: 0 | D27: =SUMIF('PO''s '!$E$2:E116,'P&L'!A27,'PO''s '!$D$2:D116) -> 60000 | E27: =SUM(C27-D27) -> -60000
A28: Electrical Engineering | B28: 0 | C28: 0 | D28: =SUMIF('PO''s '!$E$2:E117,'P&L'!A28,'PO''s '!$D$2:D117) -> 7500 | E28: =SUM(C28-D28) -> -7500
A29: CMS | B29: 0 | C29: 0 | D29: =SUMIF('PO''s '!$E$2:E118,'P&L'!A29,'PO''s '!$D$2:D118) -> 0 | E29: =SUM(C29-D29) -> 0
A30: Parts/Labor | B30: 0 | C30: 0 | D30: =SUMIF('PO''s '!$E$2:E119,'P&L'!A30,'PO''s '!$D$2:D119) -> 0 | E30: =SUM(C30-D30) -> 0
A31: Tax | B31: 0 | C31: 0 | D31: =SUMIF('PO''s '!$E$2:E120,'P&L'!A31,'PO''s '!$D$2:D120) -> 0 | E31: =SUM(C31-D31) -> 0
A32: Bond | B32: 0 | C32: 0 | D32: =SUMIF('PO''s '!$E$2:E121,'P&L'!A32,'PO''s '!$D$2:D121) -> 0 | E32: =SUM(C32-D32) -> 0
B33: 0 | C33: 0 | D33: =SUMIF('PO''s '!$E$2:E122,'P&L'!A33,'PO''s '!$D$2:D122) -> 0 | E33: =SUM(C33-D33) -> 0
B34: 0 | C34: 0 | D34: =SUMIF('PO''s '!$E$2:E123,'P&L'!A34,'PO''s '!$D$2:D123) -> 0 | E34: =SUM(C34-D34) -> 0
B35: 0 | C35: 0 | D35: =SUMIF('PO''s '!$E$2:E124,'P&L'!A35,'PO''s '!$D$2:D124) -> 0 | E35: =SUM(C35-D35) -> 0
A36: BASE CONTRACT TOTAL | B36: =SUM(B23:B35) -> 0 | C36: =SUM(C23:C35) -> 0 | D36: =SUM(D23:D35) -> 329747 | E36: =SUM(E23:E35) -> -329747
D37: =SUMIF('PO''s '!$E$2:E126,'P&L'!A37,'PO''s '!$D$2:D126) -> 0 | E37: =SUM(C37-D37) -> 0
D38: =SUMIF('PO''s '!$E$2:E127,'P&L'!A38,'PO''s '!$D$2:D127) -> 0 | E38: =SUM(C38-D38) -> 0
D39: =SUMIF('PO''s '!$E$2:E128,'P&L'!A39,'PO''s '!$D$2:D128) -> 0 | E39: =SUM(C39-D39) -> 0
D40: =SUMIF('PO''s '!$E$2:E129,'P&L'!A40,'PO''s '!$D$2:D129) -> 0 | E40: =SUM(C40-D40) -> 0
D41: =SUMIF('PO''s '!$E$2:E130,'P&L'!A41,'PO''s '!$D$2:D130) -> 0 | E41: =SUM(C41-D41) -> 0
A42: CHANGE ORDER TOTAL | B42: =SUM(B37:B41) -> 0 | C42: =SUM(C37:C41) -> 0 | D42: =SUM(D37:D41) -> 0 | E42: =SUM(E37:E41) -> 0
...

Sheet PO's 
A1: Number | B1: Washington Commanders | C1: Title | D1: Original Contract Amount | E1: 50/20/20/10
A2: 106963-001 | B2: SEATTLE STRUCTURAL PS INC | C2: Structural Engineering | D2: 20000 | E2: Structural Engineering
A3: 106963-002 | B3: PENO ENGINEERING LLC | C3: 45870 | D3: 10000 | E3: 0.5 | F3: 0.2 | G3: 0.2 | H3: 0.1
A4: 106963-003 | B4: Fairplay Corporation | C4: 45870 | D4: 55237.5 | E4: Courtside | I4: CONTRACT BUDGET - WARRANTY,SERVICE TAX INCL.
A5: 106963-004 | B5: HOIST SALES & SERVICE | C5: Chain Hoists | D5: 94724 | E5: Install
A6: 106963-005 | B6: LG ELECTRONICS ALABAMA INC | C6: LED | D6: 185556 | I6: Revenue | J6: Budgeted Cost | K6: Margin
B7: LG ELECTRONICS ALABAMA INC | C7: Shipping | D7: 32148 | H7: TOTAL BASE CONTRACT | I7: 175000 | J7: 101127.02 | K7: =I7-J7 -> 73872.98
A8: 106963-005 | B8: Yaham Hong Kong Limited | C8: LED | D8: 151835 | E8: LED | I8: CHANGE ORDERS
A9: 106963-006 | B9: OES Inc. | C9: OES | D9: 42912 | E9: Scoring | I9: Revenue | J9: Budgeted Cost | K9: Margin
A10: 106963-007 | B10: SEATTLE STRUCTURAL PS INC | C10: Structural Engineering | D10: 40000 | E10: Structural Engineering | H10: Total Change Order(s) Amount | I10: =D42 -> 0 | J10: =E42 -> 0 | K10: =I10-J10 -> 0
A11: 106963-008 | B11: PENO ENGINEERING LLC | C11: Electrical Engineering | D11: 7500 | E11: Electrical Engineering | I11: REVISED CONTRACT TOTAL
A12: 106963-009 | B12: Lynnlink Visual Elements LLC | C12: Processing | D12: 15688 | E12: LED | H12: Grand Total | I12: =I7+I10 -> 175000 | J12: =J7+J10 -> 101127.02 | K12: =I12-J12 -> 73872.98
A13: 106963-010 | B13: LG ELECTRONICS ALABAMA INC | C13: Grand Hall
A14: 106963-011 | I14: Revenue | J14: Actual Cost | K14: Margin
A15: 106963-012 | H15: Margin Tracking | I15: =I12 -> 175000 | J15: =J12 -> 101127.02 | K15: =I15-J15 -> 73872.98
A16: 106963-013
A17: 106963-014
A18: 106963-015 | I18: Services/Warranty | J18: Revenue | K18: Budgeted Cost
A19: 106963-016 | I19: Advertising
A20: 106963-017 | I20: Parts/Labor | J20: 23707 | K20: 13750
A21: 106963-018 | I21: Graphics/Design
A22: 106963-019 | I22: Software License | J22: ='[298]Cost Summary'!L97 -> 0
A23: 106963-020 | I23: Tax
A24: 106963-021 | I24: Total | J24: =SUM(J19:J23) -> 23707 | K24: =SUM(K19:K23) -> 13750
A25: 106963-022
A26: 106963-023
A27: 106963-024
A28: 106963-025
A29: 106963-026
A30: 106963-027
A31: 106963-028
A32: 106963-029
A33: 106963-030
A34: 106963-031
A35: 106963-032
A36: 106963-033
... A113: 106963-110

Sheet Cash Flow
D1: Payment Terms: | E1: 50/20/20/10
B2: Project #: | D2: Payment Phases | E2: Contract Signed | F2: Product Shipping | G2: Substantial Completion | H2: Sign Off
B3: Contract Award Date | C3: 45748 | D3: Percentages | E3: 0.5 | F3: 0.2 | G3: 0.2 | H3: 0.1
B4: Scheduled Completion Date | C4: 45992
B6: Revenue | C6: Expenses | D6: Gross Profit | E6: Gross Profit % | F6: Budget Tracking (+/-)
B7: =C22 -> 0 | C7: =D36 -> 0 | D7: =B7-C7 -> 0 | E7: =D7/B7 -> #DIV/0! | F7: =C7-D36 -> 0
A9: Month | F9: =C3 -> 45748 | G9: =DATE(YEAR(F9),MONTH(F9)+1,DAY(F9)) -> 45778 | H9: =DATE(YEAR(G9),MONTH(G9)+1,DAY(G9)) -> 45809 | I9: =DATE(YEAR(H9),MONTH(H9)+1,DAY(H9)) -> 45839 | J9: =DATE(YEAR(I9),MONTH(I9)+1,DAY(I9)) -> 45870 | K9: =DATE(YEAR(J9),MONTH(J9)+1,DAY(J9)) -> 45901 | L9: =DATE(YEAR(K9),MONTH(K9)+1,DAY(K9)) -> 45931 | M9: =DATE(YEAR(L9),MONTH(L9)+1,DAY(L9)) -> 45962 | N9: =DATE(YEAR(M9),MONTH(M9)+1,DAY(M9)) -> 45992 | ... Q9: =DATE(YEAR(P9),MONTH(P9)+1,DAY(P9)) -> 46082 | R9: FY25 | S9: FY26
A10: Revenue | C10: Amount | D10: Date Submitted
A11: 1 | C11: 0 | F11: 0 | G11: 0 | H11: 0 | I11: 0 | J11: 0 | K11: 0 | L11: 0 | M11: 0 | N11: 0 | O11: 0 | P11: 0 | Q11: 0 | R11: =SUM(F11:N11) -> 0 | S11: =SUM(O11:Q11) -> 0
A12: 2 | C12: 0 | F12: 0 | G12: 0 | H12: 0 | I12: 0 | J12: 0 | K12: 0 | L12: 0 | M12: 0 | N12: 0 | O12: 0 | P12: 0 | Q12: 0 | R12: =SUM(F12:N12) -> 0 | S12: =SUM(O12:Q12) -> 0
A13: 3 | C13: 0 | F13: 0 | G13: 0 | H13: 0 | I13: 0 | J13: 0 | K13: 0 | L13: 0 | M13: 0 | N13: 0 | O13: 0 | P13: 0 | Q13: 0 | R13: =SUM(F13:N13) -> 0 | S13: =SUM(O13:Q13) -> 0
A14: 4 | C14: 0 | F14: 0 | G14: 0 | H14: 0 | I14: 0 | J14: 0 | K14: 0 | L14: 0 | M14: 0 | N14: 0 | O14: 0 | P14: 0 | Q14: 0 | R14: =SUM(F14:N14) -> 0 | S14: =SUM(O14:Q14) -> 0
A15: 5 | C15: 0 | F15: 0 | G15: 0 | H15: 0 | I15: 0 | J15: 0 | K15: 0 | L15: 0 | M15: 0 | N15: 0 | O15: 0 | P15: 0 | Q15: 0 | R15: =SUM(F15:N15) -> 0 | S15: =SUM(O15:Q15) -> 0
A16: 6 | C16: 0 | F16: 0 | G16: 0 | H16: 0 | I16: 0 | J16: 0 | K16: 0 | L16: 0 | M16: 0 | N16: 0 | O16: 0 | P16: 0 | Q16: 0 | R16: =SUM(F16:N16) -> 0 | S16: =SUM(O16:Q16) -> 0
A17: 7 | C17: 0 | F17: 0 | G17: 0 | H17: 0 | I17: 0 | J17: 0 | K17: 0 | L17: 0 | M17: 0 | N17: 0 | O17: 0 | P17: 0 | Q17: 0 | R17: =SUM(F17:N17) -> 0 | S17: =SUM(O17:Q17) -> 0
A18: 8 | C18: 0 | F18: 0 | G18: 0 | H18: 0 | I18: 0 | J18: 0 | K18: 0 | L18: 0 | M18: 0 | N18: 0 | O18: 0 | P18: 0 | Q18: 0 | R18: =SUM(F18:N18) -> 0 | S18: =SUM(O18:Q18) -> 0
A19: 9 | C19: 0 | F19: 0 | G19: 0 | H19: 0 | I19: 0 | J19: 0 | K19: 0 | L19: 0 | M19: 0 | N19: 0 | O19: 0 | P19: 0 | Q19: 0 | R19: =SUM(F19:N19) -> 0 | S19: =SUM(O19:Q19) -> 0
A20: 10 | C20: 0 | F20: 0 | G20: 0 | H20: 0 | I20: 0 | J20: 0 | K20: 0 | L20: 0 | M20: 0 | N20: 0 | O20: 0 | P20: 0 | Q20: 0 | R20: =SUM(F20:N20) -> 0 | S20: =SUM(O20:Q20) -> 0
C21: 0 | F21: 0 | G21: 0 | H21: 0 | I21: 0 | J21: 0 | K21: 0 | L21: 0 | M21: 0 | N21: 0 | O21: 0 | P21: 0 | Q21: 0 | R21: =SUM(F21:N21) -> 0 | S21: =SUM(O21:Q21) -> 0
A22: Total Revenue | C22: =SUM(C11:C21) -> 0 | F22: =SUM(F11:F21) -> 0 | G22: =SUM(G11:G21) -> 0 | H22: =SUM(H11:H21) -> 0 | I22: =SUM(I11:I21) -> 0 | J22: =SUM(J11:J21) -> 0 | K22: =SUM(K11:K21) -> 0 | L22: =SUM(L11:L21) -> 0 | M22: =SUM(M11:M21) -> 0 | ... S22: =SUM(S11:S21) -> 0
A24: Cost of Rev | C24: Budget | D24: Committed Amt. | E24: Paid | R24: FY25 | S24: FY26
A25: 1 | C25: 0 | D25: 0 | E25: 0 | F25: 0 | G25: 0 | H25: 0 | I25: 0 | J25: 0 | K25: 0 | L25: 0 | M25: 0 | N25: 0 | O25: 0 | P25: 0 | Q25: 0 | R25: =SUM(F25:N25) -> 0 | S25: =SUM(O25:Q25) -> 0
A26: 2 | C26: 0 | D26: 0 | E26: 0 | F26: 0 | G26: 0 | H26: 0 | I26: 0 | J26: 0 | K26: 0 | L26: 0 | M26: 0 | N26: 0 | O26: 0 | P26: 0 | Q26: 0 | R26: =SUM(F26:N26) -> 0 | S26: =SUM(O26:Q26) -> 0
A27: 3 | C27: 0 | D27: 0 | E27: 0 | F27: 0 | G27: 0 | H27: 0 | I27: 0 | J27: 0 | K27: 0 | L27: 0 | M27: 0 | N27: 0 | O27: 0 | P27: 0 | Q27: 0 | R27: =SUM(F27:N27) -> 0 | S27: =SUM(O27:Q27) -> 0
A28: 4 | C28: 0 | D28: 0 | E28: 0 | F28: 0 | G28: 0 | H28: 0 | I28: 0 | J28: 0 | K28: 0 | L28: 0 | M28: 0 | N28: 0 | O28: 0 | P28: 0 | Q28: 0 | R28: =SUM(F28:N28) -> 0 | S28: =SUM(O28:Q28) -> 0
A29: 5 | C29: 0 | D29: 0 | E29: 0 | F29: 0 | G29: 0 | H29: 0 | I29: 0 | J29: 0 | K29: 0 | L29: 0 | M29: 0 | N29: 0 | O29: 0 | P29: 0 | Q29: 0 | R29: =SUM(F29:N29) -> 0 | S29: =SUM(O29:Q29) -> 0
A30: 6 | C30: 0 | D30: 0 | E30: 0 | F30: 0 | G30: 0 | H30: 0 | I30: 0 | J30: 0 | K30: 0 | L30: 0 | M30: 0 | N30: 0 | O30: 0 | P30: 0 | Q30: 0 | R30: =SUM(F30:N30) -> 0 | S30: =SUM(O30:Q30) -> 0
A31: 7 | C31: 0 | D31: 0 | E31: 0 | F31: 0 | G31: 0 | H31: 0 | I31: 0 | J31: 0 | K31: 0 | L31: 0 | M31: 0 | N31: 0 | O31: 0 | P31: 0 | Q31: 0 | R31: =SUM(F31:N31) -> 0 | S31: =SUM(O31:Q31) -> 0
A32: 8 | C32: 0 | D32: 0 | E32: 0 | F32: 0 | G32: 0 | H32: 0 | I32: 0 | J32: 0 | K32: 0 | L32: 0 | M32: 0 | N32: 0 | O32: 0 | P32: 0 | Q32: 0 | R32: =SUM(F32:N32) -> 0 | S32: =SUM(O32:Q32) -> 0
A33: 9 | C33: 0 | D33: 0 | E33: 0 | F33: 0 | G33: 0 | H33: 0 | I33: 0 | J33: 0 | K33: 0 | L33: 0 | M33: 0 | N33: 0 | O33: 0 | P33: 0 | Q33: 0 | R33: =SUM(F33:N33) -> 0 | S33: =SUM(O33:Q33) -> 0
A34: 10 | C34: 0 | D34: 0 | E34: 0 | F34: 0 | G34: 0 | H34: 0 | I34: 0 | J34: 0 | K34: 0 | L34: 0 | M34: 0 | N34: 0 | O34: 0 | P34: 0 | Q34: 0 | R34: =SUM(F34:N34) -> 0 | S34: =SUM(O34:Q34) -> 0
C35: 0 | D35: 0 | E35: 0 | F35: 0 | G35: 0 | H35: 0 | I35: 0 | J35: 0 | K35: 0 | L35: 0 | M35: 0 | N35: 0 | O35: 0 | P35: 0 | Q35: 0 | R35: =SUM(F35:N35) -> 0 | S35: =SUM(O35:Q35) -> 0
A36: Monthly Total COR | C36: =SUM(C25:C35) -> 0 | D36: =SUM(D25:D35) -> 0 | E36: =SUM(E25:E35) -> 0 | F36: =SUM(F25:F35) -> 0 | G36: =SUM(G25:G35) -> 0 | H36: =SUM(H25:H35) -> 0 | I36: =SUM(I25:I35) -> 0 | J36: =SUM(J25:J35) -> 0 | ... Q36: =SUM(Q25:Q35) -> 0 | R36: =SUM(F36:Q36) -> 0 | S36: =SUM(G36:R36) -> 0
A38: Monthly Gross Profit | F38: =F22-F36 -> 0 | G38: =G22-G36 -> 0 | H38: =H22-H36 -> 0 | I38: =I22-I36 -> 0 | J38: =J22-J36 -> 0 | K38: =K22-K36 -> 0 | L38: =L22-L36 -> 0 | M38: =M22-M36 -> 0 | ... Q38: =Q22-Q36 -> 0
A40: Project Cash Flow | F40: =F22-F36 -> 0 | G40: =F40+G38 -> 0 | H40: =G40+H38 -> 0 | I40: =H40+I38 -> 0 | J40: =I40+J38 -> 0 | K40: =J40+K38 -> 0 | L40: =K40+L38 -> 0 | M40: =L40+M38 -> 0 | N40: =M40+N38 -> 0 | ... Q40: =P40+Q38 -> 0

Sheet Margin Analysis
B2: Project Name: Cleveland Browns - Huntington Bank Field (Budgets)
B3: =TODAY() -> 46043
B4: Revised By: JSR
B6: ='LED Cost Sheet'!A4 -> LED Video Displays | C6: Cost | D6: Selling Price | E6: Margin $ | F6: Margin %
B7: AV Display Controls & Scoreboards (Ross & OES) | C7: ='Install (Base)'!H121+'Install (Base)'!H99 -> 2000000 | D7: ='Install (Base)'!J121+'Install (Base)'!J99 -> 2500000 | E7: =D7-C7 -> 500000 | F7: =E7/D7 -> 0.2
B8: ='LED Cost Sheet'!A7 -> Cleveland Social North Left - LED Display - 4' H x 30' W - 1.2mm (Outdoor) | C8: ='LED Cost Sheet'!V7 -> 145461.52 | D8: ='LED Cost Sheet'!X7 -> 171131.2 | E8: =D8-C8 -> 25669.68 | F8: =E8/D8 -> 0.15
B9: ='LED Cost Sheet'!A10 -> Cleveland Social North Right - LED Display - 4' H x 30' W - 1.2mm (Outdoor) | C9: ='LED Cost Sheet'!V10 -> 145461.52 | D9: ='LED Cost Sheet'!X10 -> 171131.2 | E9: =D9-C9 -> 25669.68 | F9: =E9/D9 -> 0.15
B10: ='LED Cost Sheet'!A13 -> Cleveland Social South Left - LED Display - 4' H x 30' W - 1.2mm (Outdoor) | C10: ='LED Cost Sheet'!V13 -> 145461.52 | D10: ='LED Cost Sheet'!X13 -> 171131.2 | E10: =D10-C10 -> 25669.68 | F10: =E10/D10 -> 0.15
B11: ='LED Cost Sheet'!A16 -> Cleveland Social South Right - LED Display - 4' H x 30' W - 1.2mm (Outdoor) | C11: ='LED Cost Sheet'!V16 -> 145461.52 | D11: ='LED Cost Sheet'!X16 -> 171131.2 | E11: =D11-C11 -> 25669.68 | F11: =E11/D11 -> 0.15
B12: ='LED Cost Sheet'!A19 -> Dawg Pound Board - LED Display - 40'9" H x 344' W - 10mm (Outdoor) | C12: ='LED Cost Sheet'!V19 -> 6848011.1 | D12: ='LED Cost Sheet'!X19 -> 8056483.6 | E12: =D12-C12 -> 1208472.5 | F12: =E12/D12 -> 0.15
B13: ='LED Cost Sheet'!A22 -> Endzone Video Board - LED Display - 40' H x 260' W - 10mm (Outdoor) | C13: ='LED Cost Sheet'!V22 -> 5012790.4 | D13: ='LED Cost Sheet'!X22 -> 5897400.5 | E13: =D13-C13 -> 884610.07 | F13: =E13/D13 -> 0.15
B14: ='LED Cost Sheet'!A25 -> Exterior Video Board East - LED Display - 56'6" H x 224'1" W - 10mm (Outdoor) | C14: ='LED Cost Sheet'!V25 -> 6278567.6 | D14: ='LED Cost Sheet'!X25 -> 7386550.1 | E14: =D14-C14 -> 1107982.5 | F14: =E14/D14 -> 0.15
B15: ='LED Cost Sheet'!A28 -> Exterior Video Board West - LED Display - 53'6" H x 211'2" W - 10mm (Outdoor) | C15: ='LED Cost Sheet'!V28 -> 5570875.8 | D15: ='LED Cost Sheet'!X28 -> 6553971.5 | E15: =D15-C15 -> 983095.73 | F15: =E15/D15 -> 0.15
B16: ='LED Cost Sheet'!A31 -> Grand Concourse Bar Board 01 - LED Display - 36' H x 36'8" W - 10mm (Outdoor) | C16: ='LED Cost Sheet'!V31 -> 639818.19 | D16: ='LED Cost Sheet'!X31 -> 752727.28 | E16: =D16-C16 -> 112909.09 | F16: =E16/D16 -> 0.15
B17: ='LED Cost Sheet'!A34 -> Grand Concourse Bar Board 02 - LED Display - 36' H x 36'8" W - 10mm (Outdoor) | C17: ='LED Cost Sheet'!V34 -> 639818.19 | D17: ='LED Cost Sheet'!X34 -> 752727.28 | E17: =D17-C17 -> 112909.09 | F17: =E17/D17 -> 0.15
B18: ='LED Cost Sheet'!A37 -> Grand Concourse Bar Board 04 - LED Display - 36' H x 36'8" W - 10mm (Outdoor) | C18: ='LED Cost Sheet'!V37 -> 639818.19 | D18: ='LED Cost Sheet'!X37 -> 752727.28 | E18: =D18-C18 -> 112909.09 | F18: =E18/D18 -> 0.15
B19: ='LED Cost Sheet'!A40 -> Grand Concourse Bar Board 05 - LED Display - 36' H x 36'8" W - 10mm (Outdoor) | C19: ='LED Cost Sheet'!V40 -> 639818.19 | D19: ='LED Cost Sheet'!X40 -> 752727.28 | E19: =D19-C19 -> 112909.09 | F19: =E19/D19 -> 0.15
B20: ='LED Cost Sheet'!A43 -> Interview Room - LED Display - 18' H x 32'9" W - 1.2mm (Outdoor) | C20: ='LED Cost Sheet'!V43 -> 643093.04 | D20: ='LED Cost Sheet'!X43 -> 756580.04 | E20: =D20-C20 -> 113487.01 | F20: =E20/D20 -> 0.15
B21: ='LED Cost Sheet'!A46 -> Locker Room Ceiling Video Board - LED Display - 4' H x 42' W - 1.2mm (Outdoor) | C21: ='LED Cost Sheet'!V46 -> 206708.48 | D21: ='LED Cost Sheet'!X46 -> 243186.44 | E21: =D21-C21 -> 36477.966 | F21: =E21/D21 -> 0.15
B22: ='LED Cost Sheet'!A49 -> NE Wrap Around - LED Display - 8' H x 8'6" W - 1.2mm (Outdoor) | C22: ='LED Cost Sheet'!V49 -> 75793.108 | D22: ='LED Cost Sheet'!X49 -> 89168.362 | E22: =D22-C22 -> 13375.254 | F22: =E22/D22 -> 0.15
B23: ='LED Cost Sheet'!A52 -> NE Wrap Around - LED Display - 8' H x 8'6" W - 1.2mm (Outdoor) | C23: ='LED Cost Sheet'!V52 -> 75793.108 | D23: ='LED Cost Sheet'!X52 -> 89168.362 | E23: =D23-C23 -> 13375.254 | F23: =E23/D23 -> 0.15
B24: ='LED Cost Sheet'!A55 -> NW Tap Bar - LED Display - 4' H x 30' W - 1.2mm (Outdoor) | C24: ='LED Cost Sheet'!V55 -> 145461.52 | D24: ='LED Cost Sheet'!X55 -> 171131.2 | E24: =D24-C24 -> 25669.68 | F24: =E24/D24 -> 0.15
B25: ='LED Cost Sheet'!A58 -> NW Wrap Around - LED Display - 8' H x 8'6" W - 1.2mm (Outdoor) | C25: ='LED Cost Sheet'!V58 -> 75793.108 | D25: ='LED Cost Sheet'!X58 -> 89168.362 | E25: =D25-C25 -> 13375.254 | F25: =E25/D25 -> 0.15
B26: ='LED Cost Sheet'!A61 -> NW Wrap Around - LED Display - 8' H x 8'6" W - 1.2mm (Outdoor) | C26: ='LED Cost Sheet'!V61 -> 75793.108 | D26: ='LED Cost Sheet'!X61 -> 89168.362 | E26: =D26-C26 -> 13375.254 | F26: =E26/D26 -> 0.15
B27: ='LED Cost Sheet'!A64 -> SE Wrap Around - LED Display - 8' H x 8'6" W - 1.2mm (Outdoor) | C27: ='LED Cost Sheet'!V64 -> 75793.108 | D27: ='LED Cost Sheet'!X64 -> 89168.362 | E27: =D27-C27 -> 13375.254 | F27: =E27/D27 -> 0.15
B28: ='LED Cost Sheet'!A67 -> SE Wrap Around - LED Display - 8' H x 8'6" W - 1.2mm (Outdoor) | C28: ='LED Cost Sheet'!V67 -> 75793.108 | D28: ='LED Cost Sheet'!X67 -> 89168.362 | E28: =D28-C28 -> 13375.254 | F28: =E28/D28 -> 0.15
B29: ='LED Cost Sheet'!A70 -> SW Tap Bar - LED Display - 4' H x 30' W - 1.2mm (Outdoor) | C29: ='LED Cost Sheet'!V70 -> 145461.52 | D29: ='LED Cost Sheet'!X70 -> 171131.2 | E29: =D29-C29 -> 25669.68 | F29: =E29/D29 -> 0.15
B30: ='LED Cost Sheet'!A73 -> SW Wrap Around - LED Display - 8' H x 8'6" W - 1.2mm (Outdoor) | C30: ='LED Cost Sheet'!V73 -> 75793.108 | D30: ='LED Cost Sheet'!X73 -> 89168.362 | E30: =D30-C30 -> 13375.254 | F30: =E30/D30 -> 0.15
B31: ='LED Cost Sheet'!A76 -> SW Wrap Around - LED Display - 8' H x 8'6" W - 1.2mm (Outdoor) | C31: ='LED Cost Sheet'!V76 -> 75793.108 | D31: ='LED Cost Sheet'!X76 -> 89168.362 | E31: =D31-C31 -> 13375.254 | F31: =E31/D31 -> 0.15
B32: ='LED Cost Sheet'!A79 -> Team Store Board - LED Display - 8' H x 40' W - 1.2mm (Outdoor) | C32: ='LED Cost Sheet'!V79 -> 344514.13 | D32: ='LED Cost Sheet'!X79 -> 405310.74 | E32: =D32-C32 -> 60796.611 | F32: =E32/D32 -> 0.15
B33: ='LED Cost Sheet'!A82 -> Team Tunnel At Field - LED Display - 14' H x 16'9" W - 10mm (Outdoor) | C33: ='LED Cost Sheet'!V82 -> 114585.62 | D33: ='LED Cost Sheet'!X82 -> 134806.61 | E33: =D33-C33 -> 20220.992 | F33: =E33/D33 -> 0.15
C34: =SUM(C7:C33) -> 31057533 | D34: =SUM(D7:D33) -> 36685333 | E34: =D34-C34 -> 5627799.9 | F34: =E34/D34 -> 0.15340736
B35: TAX | C35: 0 | D35: =D34*C35 -> 0
B36: BOND | C36: 0 | D36: =D34*C36 -> 0
B37: SUB TOTAL (BID FORM) | D37: =SUM(D34:D36) -> 36685333 | E37: =E34 -> 5627799.9 | F37: =E37/D37 -> 0.15340736
D41: 36685328

Sheet LED Cost Sheet
A1: Outdoor | B1: Type 1 | C1: 10mm SMD | D1: 6000 Nits
A2: Outdoor | B2: Type 2 | C2: 10mm SMD Top | D2: 6000 Nits | R2: 0.1 | U2: 12 | W2: 0.15
A3: Outdoor | B3: Type 3 | C3: 1.2mm SMD | D3: 4000 Nits
A4: LED Video Displays
E5: BID SPEC | F5: Active Display Size (Feet) | H5: Pixel Count | K5: Square Feet | L5: Quantity | N5: LED NIT | O5: LED Service | W5: LED | X5: Total
A6: OPTION | B6: Issue | C6: VENDOR | D6: PRODUCT | E6: PITCH | F6: H | G6: W | H6: H | J6: W | K6: Per Screen | L6: of Screens | M6: Total SQ FT | N6: Requirement | O6: Requirement | P6: Cost Sq. Ft | Q6: Display Cost | R6: Sponsorship | S6: Installation | T6: Electrical | U6: Shipping | V6: Total Cost | W6: Margin | X6: Price | Y6: ANC Margin | Z6: Bond Cost | AA6: Total with Bond | AB6: Selling Sq. Ft | AC6: Shipping Sale Price
A7: Cleveland Social North Left - LED Display - 4' H x 30' W - 1.2mm (Outdoor) | B7: Type 3 | E7: 1.875mm | F7: =1.77*2.5 -> 4.425 | G7: =1.57*19 -> 29.83 | H7: =288*2.5 -> 720 | I7: x | J7: =256*19 -> 4864 | K7: =F7*G7 -> 131.99775 | L7: 1 | M7: =K7*L7 -> 131.99775 | N7: 4000 | O7: Front / Rear | P7: =Q7/M7 -> 750 | Q7: =M7*750 -> 98998.312 | R7: =Q7*$R$2 -> 9899.8313 | S7: =M7*150 -> 19799.662 | T7: =M7*115 -> 15179.741 | U7: =M7*$U$2 -> 1583.973 | V7: =SUM(Q7:U7) -> 145461.52 | W7: =$W$2 -> 0.15 | X7: =V7/(1-W7) -> 171131.2 | Y7: =X7-V7 -> 25669.68 | Z7: =X7*0.015 -> 2566.968 | AA7: =X7+Z7 -> 173698.17 | AB7: =X7/M7 -> 1296.4706 | AC7: =U7/(1-$W$2) -> 1863.4976
Q8: =(Q7+R7)/(1-$W$2) -> 128115.46 | S8: =S7/(1-$W$2) -> 23293.721 | T8: =T7/(1-$W$2) -> 17858.519 | U8: =U7/(1-$W$2) -> 1863.4976
A10: Cleveland Social North Right - LED Display - 4' H x 30' W - 1.2mm (Outdoor) | B10: Type 3 | E10: 1.875mm | F10: =1.77*2.5 -> 4.425 | G10: =1.57*19 -> 29.83 | H10: =288*2.5 -> 720 | I10: x | J10: =256*19 -> 4864 | K10: =F10*G10 -> 131.99775 | L10: 1 | M10: =K10*L10 -> 131.99775 | N10: 4000 | O10: Front / Rear | P10: =Q10/M10 -> 750 | Q10: =M10*750 -> 98998.312 | R10: =Q10*$R$2 -> 9899.8313 | S10: =M10*150 -> 19799.662 | T10: =M10*115 -> 15179.741 | U10: =M10*$U$2 -> 1583.973 | V10: =SUM(Q10:U10) -> 145461.52 | W10: =$W$2 -> 0.15 | X10: =V10/(1-W10) -> 171131.2 | Y10: =X10-V10 -> 25669.68 | Z10: =X10*0.015 -> 2566.968 | AA10: =X10+Z10 -> 173698.17 | AB10: =X10/M10 -> 1296.4706 | AC10: =U10/(1-$W$2) -> 1863.4976
Q11: =(Q10+R10)/(1-$W$2) -> 128115.46 | S11: =S10/(1-$W$2) -> 23293.721 | T11: =T10/(1-$W$2) -> 17858.519 | U11: =U10/(1-$W$2) -> 1863.4976
A13: Cleveland Social South Left - LED Display - 4' H x 30' W - 1.2mm (Outdoor) | B13: Type 3 | E13: 1.875mm | F13: =1.77*2.5 -> 4.425 | G13: =1.57*19 -> 29.83 | H13: =288*2.5 -> 720 | I13: x | J13: =256*19 -> 4864 | K13: =F13*G13 -> 131.99775 | L13: 1 | M13: =K13*L13 -> 131.99775 | N13: 4000 | O13: Front / Rear | P13: =Q13/M13 -> 750 | Q13: =M13*750 -> 98998.312 | R13: =Q13*$R$2 -> 9899.8313 | S13: =M13*150 -> 19799.662 | T13: =M13*115 -> 15179.741 | U13: =M13*$U$2 -> 1583.973 | V13: =SUM(Q13:U13) -> 145461.52 | W13: =$W$2 -> 0.15 | X13: =V13/(1-W13) -> 171131.2 | Y13: =X13-V13 -> 25669.68 | Z13: =X13*0.015 -> 2566.968 | AA13: =X13+Z13 -> 173698.17 | AB13: =X13/M13 -> 1296.4706 | AC13: =U13/(1-$W$2) -> 1863.4976
Q14: =(Q13+R13)/(1-$W$2) -> 128115.46 | S14: =S13/(1-$W$2) -> 23293.721 | T14: =T13/(1-$W$2) -> 17858.519 | U14: =U13/(1-$W$2) -> 1863.4976
A16: Cleveland Social South Right - LED Display - 4' H x 30' W - 1.2mm (Outdoor) | B16: Type 3 | E16: 1.875mm | F16: =1.77*2.5 -> 4.425 | G16: =1.57*19 -> 29.83 | H16: =288*2.5 -> 720 | I16: x | J16: =256*19 -> 4864 | K16: =F16*G16 -> 131.99775 | L16: 1 | M16: =K16*L16 -> 131.99775 | N16: 4000 | O16: Front / Rear | P16: =Q16/M16 -> 750 | Q16: =M16*750 -> 98998.312 | R16: =Q16*$R$2 -> 9899.8313 | S16: =M16*150 -> 19799.662 | T16: =M16*115 -> 15179.741 | U16: =M16*$U$2 -> 1583.973 | V16: =SUM(Q16:U16) -> 145461.52 | W16: =$W$2 -> 0.15 | X16: =V16/(1-W16) -> 171131.2 | Y16: =X16-V16 -> 25669.68 | Z16: =X16*0.015 -> 2566.968 | AA16: =X16+Z16 -> 173698.17 | AB16: =X16/M16 -> 1296.4706 | AC16: =U16/(1-$W$2) -> 1863.4976
Q17: =(Q16+R16)/(1-$W$2) -> 128115.46 | S17: =S16/(1-$W$2) -> 23293.721 | T17: =T16/(1-$W$2) -> 17858.519 | U17: =U16/(1-$W$2) -> 1863.4976
A19: Dawg Pound Board - LED Display - 40'9" H x 344' W - 10mm (Outdoor) | B19: Type 1 | E19: 10mm | F19: =3.28*12.334 -> 40.45552 | G19: =3.28*105 -> 344.4 | H19: =96*12.334 -> 1184.064 | I19: x | J19: =96*105 -> 10080 | K19: =F19*G19 -> 13932.881 | L19: 1 | M19: =K19*L19 -> 13932.881 | N19: 6000 | O19: Front / Rear | P19: =Q19/M19 -> 195 | Q19: =M19*195 -> 2716911.8 | R19: =Q19*$R$2 -> 271691.18 | S19: =M19*150 -> 2089932.2 | T19: =M19*115 -> 1602281.3 | U19: =M19*$U$2 -> 167194.57 | V19: =SUM(Q19:U19) -> 6848011.1 | W19: =$W$2 -> 0.15 | X19: =V19/(1-W19) -> 8056483.6 | Y19: =X19-V19 -> 1208472.5 | Z19: =X19*0.015 -> 120847.25 | AA19: =X19+Z19 -> 8177330.8 | AB19: =X19/M19 -> 578.23529 | AC19: =U19/(1-$W$2) -> 196699.5
Q20: =(Q19+R19)/(1-$W$2) -> 3516003.5 | S20: =S19/(1-$W$2) -> 2458743.7 | T20: =T19/(1-$W$2) -> 1885036.9 | U20: =U19/(1-$W$2) -> 196699.5
A22: Endzone Video Board - LED Display - 40' H x 260' W - 10mm (Outdoor) | B22: Type 1 | E22: 10mm | F22: =3.28*12 -> 39.36 | G22: =3.28*79 -> 259.12 | H22: =96*12 -> 1152 | I22: x | J22: =96*79 -> 7584 | K22: =F22*G22 -> 10198.963 | L22: 1 | M22: =K22*L22 -> 10198.963 | N22: 6000 | O22: Front / Rear | P22: =Q22/M22 -> 195 | Q22: =M22*195 -> 1988797.8 | R22: =Q22*$R$2 -> 198879.78 | S22: =M22*150 -> 1529844.5 | T22: =M22*115 -> 1172880.8 | U22: =M22*$U$2 -> 122387.56 | V22: =SUM(Q22:U22) -> 5012790.4 | W22: =$W$2 -> 0.15 | X22: =V22/(1-W22) -> 5897400.5 | Y22: =X22-V22 -> 884610.07 | Z22: =X22*0.015 -> 88461.007 | AA22: =X22+Z22 -> 5985861.5 | AB22: =X22/M22 -> 578.23529 | AC22: =U22/(1-$W$2) -> 143985.36
Q23: =(Q22+R22)/(1-$W$2) -> 2573738.4 | S23: =S22/(1-$W$2) -> 1799817 | T23: =T22/(1-$W$2) -> 1379859.7 | U23: =U22/(1-$W$2) -> 143985.36
A25: Exterior Video Board East - LED Display - 56'6" H x 224'1" W - 10mm (Outdoor) | B25: Type 1 | E25: 10mm | F25: =3.28*17.334 -> 56.85552 | G25: =3.28*68.5 -> 224.68 | H25: =96*17.334 -> 1664.064 | I25: x | J25: =96*68.5 -> 6576 | K25: =F25*G25 -> 12774.298 | L25: 1 | M25: =K25*L25 -> 12774.298 | N25: 6000 | O25: Front / Rear | P25: =Q25/M25 -> 195 | Q25: =M25*195 -> 2490988.2 | R25: =Q25*$R$2 -> 249098.82 | S25: =M25*150 -> 1916144.7 | T25: =M25*115 -> 1469044.3 | U25: =M25*$U$2 -> 153291.58 | V25: =SUM(Q25:U25) -> 6278567.6 | W25: =$W$2 -> 0.15 | X25: =V25/(1-W25) -> 7386550.1 | Y25: =X25-V25 -> 1107982.5 | Z25: =X25*0.015 -> 110798.25 | AA25: =X25+Z25 -> 7497348.3 | AB25: =X25/M25 -> 578.23529 | AC25: =U25/(1-$W$2) -> 180343.03
Q26: =(Q25+R25)/(1-$W$2) -> 3223631.7 | S26: =S25/(1-$W$2) -> 2254287.9 | T26: =T25/(1-$W$2) -> 1728287.4 | U26: =U25/(1-$W$2) -> 180343.03
A28: Exterior Video Board West - LED Display - 53'6" H x 211'2" W - 10mm (Outdoor) | B28: Type 1 | E28: 10mm | F28: =3.28*16.334 -> 53.57552 | G28: =3.28*64.5 -> 211.56 | H28: =96*16.334 -> 1568.064 | I28: x | J28: =96*64.5 -> 6192 | K28: =F28*G28 -> 11334.437 | L28: 1 | M28: =K28*L28 -> 11334.437 | N28: 6000 | O28: Front / Rear | P28: =Q28/M28 -> 195 | Q28: =M28*195 -> 2210215.2 | R28: =Q28*$R$2 -> 221021.52 | S28: =M28*150 -> 1700165.6 | T28: =M28*115 -> 1303460.3 | U28: =M28*$U$2 -> 136013.24 | V28: =SUM(Q28:U28) -> 5570875.8 | W28: =$W$2 -> 0.15 | X28: =V28/(1-W28) -> 6553971.5 | Y28: =X28-V28 -> 983095.73 | Z28: =X28*0.015 -> 98309.573 | AA28: =X28+Z28 -> 6652281.1 | AB28: =X28/M28 -> 578.23529 | AC28: =U28/(1-$W$2) -> 160015.58
Q29: =(Q28+R28)/(1-$W$2) -> 2860278.5 | S29: =S28/(1-$W$2) -> 2000194.8 | T29: =T28/(1-$W$2) -> 1533482.7 | U29: =U28/(1-$W$2) -> 160015.58
A31: Grand Concourse Bar Board 01 - LED Display - 36' H x 36'8" W - 10mm (Outdoor) | B31: Type 1 | E31: 10mm | F31: =3.28*11 -> 36.08 | G31: =3.28*11 -> 36.08 | H31: =96*11 -> 1056 | I31: x | J31: =96*11 -> 1056 | K31: =F31*G31 -> 1301.7664 | L31: 1 | M31: =K31*L31 -> 1301.7664 | N31: 6000 | O31: Front / Rear | P31: =Q31/M31 -> 195 | Q31: =M31*195 -> 253844.45 | R31: =Q31*$R$2 -> 25384.445 | S31: =M31*150 -> 195264.96 | T31: =M31*115 -> 149703.14 | U31: =M31*$U$2 -> 15621.197 | V31: =SUM(Q31:U31) -> 639818.19 | W31: =$W$2 -> 0.15 | X31: =V31/(1-W31) -> 752727.28 | Y31: =X31-V31 -> 112909.09 | Z31: =X31*0.015 -> 11290.909 | AA31: =X31+Z31 -> 764018.19 | AB31: =X31/M31 -> 578.23529 | AC31: =U31/(1-$W$2) -> 18377.879
Q32: =(Q31+R31)/(1-$W$2) -> 328504.58 | S32: =S31/(1-$W$2) -> 229723.48 | T32: =T31/(1-$W$2) -> 176121.34 | U32: =U31/(1-$W$2) -> 18377.879
A34: Grand Concourse Bar Board 02 - LED Display - 36' H x 36'8" W - 10mm (Outdoor) | B34: Type 1 | E34: 10mm | F34: =3.28*11 -> 36.08 | G34: =3.28*11 -> 36.08 | H34: =96*11 -> 1056 | I34: x | J34: =96*11 -> 1056 | K34: =F34*G34 -> 1301.7664 | L34: 1 | M34: =K34*L34 -> 1301.7664 | N34: 6000 | O34: Front / Rear | P34: =Q34/M34 -> 195 | Q34: =M34*195 -> 253844.45 | R34: =Q34*$R$2 -> 25384.445 | S34: =M34*150 -> 195264.96 | T34: =M34*115 -> 149703.14 | U34: =M34*$U$2 -> 15621.197 | V34: =SUM(Q34:U34) -> 639818.19 | W34: =$W$2 -> 0.15 | X34: =V34/(1-W34) -> 752727.28 | Y34: =X34-V34 -> 112909.09 | Z34: =X34*0.015 -> 11290.909 | AA34: =X34+Z34 -> 764018.19 | AB34: =X34/M34 -> 578.23529 | AC34: =U34/(1-$W$2) -> 18377.879
Q35: =(Q34+R34)/(1-$W$2) -> 328504.58 | S35: =S34/(1-$W$2) -> 229723.48 | T35: =T34/(1-$W$2) -> 176121.34 | U35: =U34/(1-$W$2) -> 18377.879
A37: Grand Concourse Bar Board 04 - LED Display - 36' H x 36'8" W - 10mm (Outdoor) | B37: Type 1 | E37: 10mm | F37: =3.28*11 -> 36.08 | G37: =3.28*11 -> 36.08 | H37: =96*11 -> 1056 | I37: x | J37: =96*11 -> 1056 | K37: =F37*G37 -> 1301.7664 | L37: 1 | M37: =K37*L37 -> 1301.7664 | N37: 6000 | O37: Front / Rear | P37: =Q37/M37 -> 195 | Q37: =M37*195 -> 253844.45 | R37: =Q37*$R$2 -> 25384.445 | S37: =M37*150 -> 195264.96 | T37: =M37*115 -> 149703.14 | U37: =M37*$U$2 -> 15621.197 | V37: =SUM(Q37:U37) -> 639818.19 | W37: =$W$2 -> 0.15 | X37: =V37/(1-W37) -> 752727.28 | Y37: =X37-V37 -> 112909.09 | Z37: =X37*0.015 -> 11290.909 | AA37: =X37+Z37 -> 764018.19 | AB37: =X37/M37 -> 578.23529 | AC37: =U37/(1-$W$2) -> 18377.879
Q38: =(Q37+R37)/(1-$W$2) -> 328504.58 | S38: =S37/(1-$W$2) -> 229723.48 | T38: =T37/(1-$W$2) -> 176121.34 | U38: =U37/(1-$W$2) -> 18377.879
A40: Grand Concourse Bar Board 05 - LED Display - 36' H x 36'8" W - 10mm (Outdoor) | B40: Type 1 | E40: 10mm | F40: =3.28*11 -> 36.08 | G40: =3.28*11 -> 36.08 | H40: =96*11 -> 1056 | I40: x | J40: =96*11 -> 1056 | K40: =F40*G40 -> 1301.7664 | L40: 1 | M40: =K40*L40 -> 1301.7664 | N40: 6000 | O40: Front / Rear | P40: =Q40/M40 -> 195 | Q40: =M40*195 -> 253844.45 | R40: =Q40*$R$2 -> 25384.445 | S40: =M40*150 -> 195264.96 | T40: =M40*115 -> 149703.14 | U40: =M40*$U$2 -> 15621.197 | V40: =SUM(Q40:U40) -> 639818.19 | W40: =$W$2 -> 0.15 | X40: =V40/(1-W40) -> 752727.28 | Y40: =X40-V40 -> 112909.09 | Z40: =X40*0.015 -> 11290.909 | AA40: =X40+Z40 -> 764018.19 | AB40: =X40/M40 -> 578.23529 | AC40: =U40/(1-$W$2) -> 18377.879
Q41: =(Q40+R40)/(1-$W$2) -> 328504.58 | S41: =S40/(1-$W$2) -> 229723.48 | T41: =T40/(1-$W$2) -> 176121.34 | U41: =U40/(1-$W$2) -> 18377.879
A43: Interview Room - LED Display - 18' H x 32'9" W - 1.2mm (Outdoor) | B43: Type 3 | E43: 1.875mm | F43: =1.77*10 -> 17.7 | G43: =1.57*21 -> 32.97 | H43: =288*10 -> 2880 | I43: x | J43: =256*21 -> 5376 | K43: =F43*G43 -> 583.569 | L43: 1 | M43: =K43*L43 -> 583.569 | N43: 4000 | O43: Front / Rear | P43: =Q43/M43 -> 750 | Q43: =M43*750 -> 437676.75 | R43: =Q43*$R$2 -> 43767.675 | S43: =M43*150 -> 87535.35 | T43: =M43*115 -> 67110.435 | U43: =M43*$U$2 -> 7002.828 | V43: =SUM(Q43:U43) -> 643093.04 | W43: =$W$2 -> 0.15 | X43: =V43/(1-W43) -> 756580.04 | Y43: =X43-V43 -> 113487.01 | Z43: =X43*0.015 -> 11348.701 | AA43: =X43+Z43 -> 767928.75 | AB43: =X43/M43 -> 1296.4706 | AC43: =U43/(1-$W$2) -> 8238.6212
Q44: =(Q43+R43)/(1-$W$2) -> 566405.21 | S44: =S43/(1-$W$2) -> 102982.76 | T44: =T43/(1-$W$2) -> 78953.453 | U44: =U43/(1-$W$2) -> 8238.6212
A46: Locker Room Ceiling Video Board - LED Display - 4' H x 42' W - 1.2mm (Outdoor) | B46: Type 3 | E46: 1.875mm | F46: =1.77*2.5 -> 4.425 | G46: =1.57*27 -> 42.39 | H46: =288*2.5 -> 720 | I46: x | J46: =256*27 -> 6912 | K46: =F46*G46 -> 187.57575 | L46: 1 | M46: =K46*L46 -> 187.57575 | N46: 4000 | O46: Front / Rear | P46: =Q46/M46 -> 750 | Q46: =M46*750 -> 140681.81 | R46: =Q46*$R$2 -> 14068.181 | S46: =M46*150 -> 28136.362 | T46: =M46*115 -> 21571.211 | U46: =M46*$U$2 -> 2250.909 | V46: =SUM(Q46:U46) -> 206708.48 | W46: =$W$2 -> 0.15 | X46: =V46/(1-W46) -> 243186.44 | Y46: =X46-V46 -> 36477.966 | Z46: =X46*0.015 -> 3647.7966 | AA46: =X46+Z46 -> 246834.24 | AB46: =X46/M46 -> 1296.4706 | AC46: =U46/(1-$W$2) -> 2648.1282
Q47: =(Q46+R46)/(1-$W$2) -> 182058.82 | S47: =S46/(1-$W$2) -> 33101.603 | T47: =T46/(1-$W$2) -> 25377.896 | U47: =U46/(1-$W$2) -> 2648.1282
A49: NE Wrap Around - LED Display - 8' H x 8'6" W - 1.2mm (Outdoor) | B49: Type 3 | E49: 1.875mm | F49: =1.77*4.5 -> 7.965 | G49: =1.57*5.5 -> 8.635 | H49: =288*4.5 -> 1296 | I49: x | J49: =256*5.5 -> 1408 | K49: =F49*G49 -> 68.777775 | L49: 1 | M49: =K49*L49 -> 68.777775 | N49: 4000 | O49: Front / Rear | P49: =Q49/M49 -> 750 | Q49: =M49*750 -> 51583.331 | R49: =Q49*$R$2 -> 5158.3331 | S49: =M49*150 -> 10316.666 | T49: =M49*115 -> 7909.4441 | U49: =M49*$U$2 -> 825.3333 | V49: =SUM(Q49:U49) -> 75793.108 | W49: =$W$2 -> 0.15 | X49: =V49/(1-W49) -> 89168.362 | Y49: =X49-V49 -> 13375.254 | Z49: =X49*0.015 -> 1337.5254 | AA49: =X49+Z49 -> 90505.888 | AB49: =X49/M49 -> 1296.4706 | AC49: =U49/(1-$W$2) -> 970.98035
Q50: =(Q49+R49)/(1-$W$2) -> 66754.899 | S50: =S49/(1-$W$2) -> 12137.254 | T50: =T49/(1-$W$2) -> 9305.2284 | U50: =U49/(1-$W$2) -> 970.98035
A52: NE Wrap Around - LED Display - 8' H x 8'6" W - 1.2mm (Outdoor) | B52: Type 3 | E52: 1.875mm | F52: =1.77*4.5 -> 7.965 | G52: =1.57*5.5 -> 8.635 | H52: =288*4.5 -> 1296 | I52: x | J52: =256*5.5 -> 1408 | K52: =F52*G52 -> 68.777775 | L52: 1 | M52: =K52*L52 -> 68.777775 | N52: 4000 | O52: Front / Rear | P52: =Q52/M52 -> 750 | Q52: =M52*750 -> 51583.331 | R52: =Q52*$R$2 -> 5158.3331 | S52: =M52*150 -> 10316.666 | T52: =M52*115 -> 7909.4441 | U52: =M52*$U$2 -> 825.3333 | V52: =SUM(Q52:U52) -> 75793.108 | W52: =$W$2 -> 0.15 | X52: =V52/(1-W52) -> 89168.362 | Y52: =X52-V52 -> 13375.254 | Z52: =X52*0.015 -> 1337.5254 | AA52: =X52+Z52 -> 90505.888 | AB52: =X52/M52 -> 1296.4706 | AC52: =U52/(1-$W$2) -> 970.98035
Q53: =(Q52+R52)/(1-$W$2) -> 66754.899 | S53: =S52/(1-$W$2) -> 12137.254 | T53: =T52/(1-$W$2) -> 9305.2284 | U53: =U52/(1-$W$2) -> 970.98035
A55: NW Tap Bar - LED Display - 4' H x 30' W - 1.2mm (Outdoor) | B55: Type 3 | E55: 1.875mm | F55: =1.77*2.5 -> 4.425 | G55: =1.57*19 -> 29.83 | H55: =288*2.5 -> 720 | I55: x | J55: =256*19 -> 4864 | K55: =F55*G55 -> 131.99775 | L55: 1 | M55: =K55*L55 -> 131.99775 | N55: 4000 | O55: Front / Rear | P55: =Q55/M55 -> 750 | Q55: =M55*750 -> 98998.312 | R55: =Q55*$R$2 -> 9899.8313 | S55: =M55*150 -> 19799.662 | T55: =M55*115 -> 15179.741 | U55: =M55*$U$2 -> 1583.973 | V55: =SUM(Q55:U55) -> 145461.52 | W55: =$W$2 -> 0.15 | X55: =V55/(1-W55) -> 171131.2 | Y55: =X55-V55 -> 25669.68 | Z55: =X55*0.015 -> 2566.968 | AA55: =X55+Z55 -> 173698.17 | AB55: =X55/M55 -> 1296.4706 | AC55: =U55/(1-$W$2) -> 1863.4976
Q56: =(Q55+R55)/(1-$W$2) -> 128115.46 | S56: =S55/(1-$W$2) -> 23293.721 | T56: =T55/(1-$W$2) -> 17858.519 | U56: =U55/(1-$W$2) -> 1863.4976
...

Sheet Install (Base)
A3: ='Margin Analysis'!B2 -> Project Name: Cleveland Browns - Huntington Bank Field (Budgets)
A4: ='Margin Analysis'!B3 -> 46043
A5: ='Margin Analysis'!B4 -> Revised By: JSR
C7: Linked Margin Assignment
C8: Install Margin | D8: 0.2
C9: Electrical Margin | D9: 0.2
C10: ANC Margin | D10: 0.2
C11: Engineering and Permits | D11: 0.2
A18: ='Margin Analysis'!B7 -> AV Display Controls & Scoreboards (Ross & OES) | B18: Height | C18: Width | D18: Total Sq. Ft | E18: QTY
B19: ='LED Cost Sheet'!F7 -> 4.425 | C19: ='LED Cost Sheet'!G7 -> 29.83 | D19: =B19*C19*E19 -> 131.99775 | E19: ='LED Cost Sheet'!L7 -> 1
A20: Structural Materials: | B20: Subcontractor 1 | C20: Subcontractor 2 | D20: Subcontractor 3 | E20: 0 | F20: Additional Contingency | H20: Total Cost | I20: Install Margin | J20: Selling Price | K20: Margin
A21: PRIMARY STRUCTURE & PIERS | B21: 0 | C21: 0 | D21: 0 | E21: =E20 -> 0 | F21: =B21*E21 -> 0 | H21: =B21+F21 -> 0 | I21: =$D$8 -> 0.2 | J21: =H21/(1-I21) -> 0 | K21: =J21-H21 -> 0
A22: SUPPLY AND INSTALL PRIMARY PLYWOOD | B22: 0 | C22: 0 | D22: 0 | E22: =E20 -> 0 | F22: =B22*E22 -> 0 | H22: =B22+F22 -> 0 | I22: =$D$8 -> 0.2 | J22: =H22/(1-I22) -> 0 | K22: =J22-H22 -> 0
A23: FABRICATE SECONDARY STEEL SUBSTRUCTURE | B23: 0 | C23: 0 | D23: 0 | E23: =E20 -> 0 | F23: =B23*E23 -> 0 | H23: =B23+F23 -> 0 | I23: =$D$8 -> 0.2 | J23: =H23/(1-I23) -> 0 | K23: =J23-H23 -> 0
A24: FABRICATE CLADDING AND TRIM | B24: 0 | C24: 0 | D24: 0 | E24: =E20 -> 0 | F24: =B24*E24 -> 0 | H24: =B24+F24 -> 0 | I24: =$D$8 -> 0.2 | J24: =H24/(1-I24) -> 0 | K24: =J24-H24 -> 0
B25: 0 | C25: 0 | D25: 0 | E25: =E20 -> 0 | F25: =B25*E25 -> 0 | H25: =B25+F25 -> 0 | I25: =$D$8 -> 0.2 | J25: =H25/(1-I25) -> 0 | K25: =J25-H25 -> 0
B26: 0 | C26: 0 | D26: 0 | E26: =E20 -> 0 | F26: =B26*E26 -> 0 | H26: =B26+F26 -> 0 | I26: =$D$8 -> 0.2 | J26: =H26/(1-I26) -> 0 | K26: =J26-H26 -> 0
A27: OTHER SCOPE ITEM | B27: 0 | C27: 0 | D27: 0 | E27: =E20 -> 0 | F27: =B27*E27 -> 0 | H27: =B27+F27 -> 0 | I27: =$D$8 -> 0.2 | J27: =H27/(1-I27) -> 0 | K27: =J27-H27 -> 0
A28: OTHER SCOPE ITEM | B28: 0 | C28: 0 | D28: 0 | E28: =E20 -> 0 | F28: =B28*E28 -> 0 | H28: =B28+F28 -> 0 | I28: =$D$8 -> 0.2 | J28: =H28/(1-I28) -> 0 | K28: =J28-H28 -> 0
A29: OTHER SCOPE ITEM | B29: 0 | C29: 0 | D29: 0 | E29: =E20 -> 0 | F29: =B29*E29 -> 0 | H29: =B29+F29 -> 0 | I29: =$D$8 -> 0.2 | J29: =H29/(1-I29) -> 0 | K29: =J29-H29 -> 0
B30: 0 | C30: 0 | D30: 0 | E30: =E20 -> 0 | F30: =B30*E30 -> 0 | H30: =B30+F30 -> 0 | I30: =$D$8 -> 0.2 | J30: =H30/(1-I30) -> 0 | K30: =J30-H30 -> 0
A31: SUBTOTAL | B31: =SUM(B21:B30) -> 0 | C31: =SUM(C21:C30) -> 0 | D31: =SUM(D21:D30) -> 0 | F31: =SUM(F21:F30) -> 0 | H31: =SUM(H21:H30) -> 0 | J31: =SUM(J21:J30) -> 0 | K31: =SUM(K21:K30) -> 0
A33: Structural Labor and LED Installation | B33: Subcontractor 1 | C33: Subcontractor 2 | D33: Subcontractor 3 | E33: 0 | F33: Additional Contingency | H33: Total Cost | I33: Install Margin | J33: Selling Price | K33: Margin
A34: REMOVAL AND DISPOSAL | B34: 0 | C34: 0 | D34: 0 | E34: =E33 -> 0 | F34: =B34*E34 -> 0 | H34: =B34+F34 -> 0 | I34: =$D$8 -> 0.2 | J34: =H34/(1-I34) -> 0 | K34: =J34-H34 -> 0
A35: INSTALL SECONDARY STEEL SUBSTRUCTURE | B35: 0 | C35: 0 | D35: 0 | E35: =E33 -> 0 | F35: =B35*E35 -> 0 | H35: =B35+F35 -> 0 | I35: =$D$8 -> 0.2 | J35: =H35/(1-I35) -> 0 | K35: =J35-H35 -> 0
A36: INSTALL LED DISPLAYS | B36: 0 | C36: 0 | D36: 0 | E36: =E33 -> 0 | F36: =B36*E36 -> 0 | H36: =B36+F36 -> 0 | I36: =$D$8 -> 0.2 | J36: =H36/(1-I36) -> 0 | K36: =J36-H36 -> 0
A37: INSTALL CLADDING AND TRIM | B37: 0 | C37: 0 | D37: 0 | E37: =E33 -> 0 | F37: =B37*E37 -> 0 | H37: =B37+F37 -> 0 | I37: =$D$8 -> 0.2 | J37: =H37/(1-I37) -> 0 | K37: =J37-H37 -> 0
A38: HEAVY EQUIPMENT | B38: 0 | C38: 0 | D38: 0 | E38: =E33 -> 0 | F38: =B38*E38 -> 0 | H38: =B38+F38 -> 0 | I38: =$D$8 -> 0.2 | J38: =H38/(1-I38) -> 0 | K38: =J38-H38 -> 0
B39: 0 | C39: 0 | D39: 0 | E39: =E33 -> 0 | F39: =B39*E39 -> 0 | H39: =B39+F39 -> 0 | I39: =$D$8 -> 0.2 | J39: =H39/(1-I39) -> 0 | K39: =J39-H39 -> 0
A40: PM/GENERAL CONDITIONS/TRAVEL | B40: 0 | C40: 0 | D40: 0 | E40: =E33 -> 0 | F40: =B40*E40 -> 0 | H40: =B40+F40 -> 0 | I40: =$D$8 -> 0.2 | J40: =H40/(1-I40) -> 0 | K40: =J40-H40 -> 0
B41: 0 | C41: 0 | D41: 0 | E41: =E33 -> 0 | F41: =B41*E41 -> 0 | H41: =B41+F41 -> 0 | I41: =$D$8 -> 0.2 | J41: =H41/(1-I41) -> 0 | K41: =J41-H41 -> 0
A42: OTHER SCOPE ITEM | B42: 0 | C42: 0 | D42: 0 | E42: =E33 -> 0 | F42: =B42*E42 -> 0 | H42: =B42+F42 -> 0 | I42: =$D$8 -> 0.2 | J42: =H42/(1-I42) -> 0 | K42: =J42-H42 -> 0
A43: OTHER SCOPE ITEM | B43: 0 | C43: 0 | D43: 0 | E43: =E33 -> 0 | F43: =B43*E43 -> 0 | H43: =B43+F43 -> 0 | I43: =$D$8 -> 0.2 | J43: =H43/(1-I43) -> 0 | K43: =J43-H43 -> 0
A44: OTHER SCOPE ITEM | B44: 0 | C44: 0 | D44: 0 | E44: =E33 -> 0 | F44: =B44*E44 -> 0 | H44: =B44+F44 -> 0 | I44: =$D$8 -> 0.2 | J44: =H44/(1-I44) -> 0 | K44: =J44-H44 -> 0
B45: 0 | C45: 0 | D45: 0 | E45: =E33 -> 0 | F45: =B45*E45 -> 0 | H45: =B45+F45 -> 0 | I45: =$D$8 -> 0.2 | J45: =H45/(1-I45) -> 0 | K45: =J45-H45 -> 0
A46: SUBTOTAL | B46: =SUM(B34:B45) -> 0 | C46: =SUM(C34:C45) -> 0 | D46: =SUM(D34:D45) -> 0 | F46: =SUM(F34:F45) -> 0 | H46: =SUM(H34:H45) -> 0 | J46: =SUM(J34:J45) -> 0 | K46: =SUM(K34:K45) -> 0
A48: Electrical and Data - Materials and Subcontracting: | B48: Subcontractor 1 | C48: Subcontractor 2 | D48: Subcontractor 3 | E48: 0 | F48: Additional Contingency | H48: Total Cost | I48: Electrical Margin | J48: Selling Price | K48: Margin
A49: Electrical - Materials | B49: 0 | C49: 0 | E49: =E48 -> 0 | F49: =B49*E49 -> 0 | H49: =B49+F49 -> 0 | I49: =$D$9 -> 0.2 | J49: =H49/(1-I49) -> 0 | K49: =J49-H49 -> 0
A50: Data - Materials | B50: 0 | C50: 0 | E50: =E48 -> 0 | F50: =B50*E50 -> 0 | H50: =B50+F50 -> 0 | I50: =$D$9 -> 0.2 | J50: =H50/(1-I50) -> 0 | K50: =J50-H50 -> 0
A51: Electrical - Labor | B51: 0 | C51: 0 | E51: =E48 -> 0 | F51: =B51*E51 -> 0 | H51: =B51+F51 -> 0 | I51: =$D$9 -> 0.2 | J51: =H51/(1-I51) -> 0 | K51: =J51-H51 -> 0
...

Sheet Resp Matrix - ROM Example
A1: Project: | B1: ROM Proposal
A2: Date: | B2: 45881
B4: Administrative | C4: YES | D4: NO
B6: Physical Installation | C6: ANC | D6: Purchaser
B7: ANC assumes all base building structure is to be provided by others or is existing and is of sufficient capacity to support the proposed display systems. | C7: Include Statement
B8: ANC has included removal and disposal of any existing signage and display systems that would be replaced by those systems that are part of this ROM proposal. | C8: Include Statement
B9: ANC assumes reasonable access will be provided to the installation team and any unknown site conditions such as lane closures, site protection, permitting, etc is not currently in this ROM Proposal. | C9: Include Statement
B10: ANC assumes all base building structure is to be provided by others or is existing and is of sufficient capacity to support the proposed display systems. Any shoring or modifications to existing structure could result in additional cost. | C10: Include Statement
B11: Electrical & Data Installation | C11: ANC | D11: Purchaser
B12: ANC assumes primary power feed will be provided by others or is existing, within 5' of the display location with sufficient amps for ANC proposed display(s); typically 208v 3-phase. | C12: Include Statement
B13: ANC assumes all secondary power distribution, which may include breaker panels, disconnects, pathway, etc may be included in this ROM Estimate | C13: Include Statement
B14: ANC assumes all data pathway is provided by others or is existing, but ANC will provide data cabling and labor to pull cable form control location to the display(s). | D14: x
B15: ANC assumes all data pathways and cables are provided and existing. Any modifications or additional cabling pulls required could result in additional cost. | C15: Include Statement
B16: Control System | C16: ANC | D16: Purchaser
B17: ANC has provided display processors only. Content creation studio and content delivery system is not included at this time. | C17: Include Statement
B18: Training | C18: ANC | D18: Column1
B19: ANC will provide appropriate on-site operation and Maintenance Training | C19: Included Statement
B20: Provide sign off list for all training to be distributed to all parties upon completion. | C20: X
B21: Perform one (1) day of maintenance training. | C21: X
B22: Perform two (2) days of control system operation.
B23: Perform final systems testing and commissioning. | C23: X
B24: Project Close- Out | C24: ANC | D24: Column1
B25: Site walk thru to conduct final inspection of punch list items with ANC
B26: Completion of punch list items | C26: X
B27: General Conditions | C27: YES | D27: No
B28: ANC has provided a parts only warranty, excluding on-site labor, on all products consistent with the factory supplier and/or 3rd party vendor. Warranty Terms and Conditions to be defined. | C28: Included Statement
B29: ANC has included installation pricing with Union labor rates and/or prevailing wage negotiation. | D29: X
B30: ANC has not included bonding of any kind. | C30: Included Statement
B31: ANC has not included any tax in the proposal. Any and all sales and use taxes, including, but not limited to, any import or associated duties, fees, tariffs as well other excises and other charges, including without limitation VAT/Sales Tax, (“collectively referred to as Government Charges”) now or henceforth levied on any date in connection with the sale of the LED System shall be the full responsibility of the Purchaser. Purchaser shall reimburse ANC for any and all Government Charges ANC may advance on Purchaser’s behalf. Purchaser acknowledges that neither ANC nor Purchaser may have advance knowledge of such Government Charges. ANC has excluded any and all taxes from the pricing in the enclosed proposal. | C31: Included Statement
B32: Shipping (Ocean Freight Shipping) included in quote at current shipping pricing. Shipping pricing is subject to change due to continued global impacts of the Covid pandemic. Any increase in costs will be responsibility of Purchaser. Current Ocean Freight timelines are approximately 6 weeks. Current Air Freight timelines are approximately 2 weeks. | C32: Included Statement
B33: The Purchaser acknowledges that amidst the duration of the Covid-19 pandemic (“Pandemic”) and thereafter for some undefined period of time, there may be consequences of the Pandemic or adverse market conditions (whether or not sudden or unpredictable) that could render either party’s performance. ANC shall not be responsible for any additional compensation hereunder or lost revenues or profits, damages, costs, or overhead incurred by the Purchaser relating to or arising out of (I) breakdowns in commercial negotiations with equipment or parts’ suppliers; (ii) delays in shipping or manufacturing or the availability of LED or LCD equipment or parts during the Term (iii) delays in third-party contractor obligations not under ANC’s control whose work precedes ANC’s obligations hereunder; (iv) Pandemic related closures of facilities or factories or contractors, whether domestic or international, or (v) employee unavailability, staffing shortages, shutdowns, postponements, or cancellations relating to or arising out of the Pandemic, whether due to illness, travel restrictions or Events of Force Majeure. | C33: Included Statement

Sheet Resp Matrix-Indoor Wall Example
A1: Project: | B1: Whatnot Lobby
A2: Date: | B2: 44797
B4: Administrative | C4: ANC | D4: Purchaser
B5: Provide accurate architectural, structural engineering, and electrical drawings or information, including exploratory surveys to confirm existing conditions if necessary. | D5: X
B6: Provide Payment and Performance Bond. | C6: NA | F6: Editable
B7: All required zoning , building, street or sidewalk closure permits, and associated costs, as required. | C7: NA | F7: Editable
B8: Shipping of all equipment to site. | C8: X
B9: Receive, unload, and inspect all new equipment upon delivery. | C9: X
B10: Provide safe storage of video equipment and control equipment in a safe, dry and secure location until installation, if required. | D10: X
B11: Unobstructed access to equipment and control room throughout installation, until equipment is 100% operational. | D11: X
B12: Engineering & Submittals | C12: ANC | D12: Purchaser
B13: Customer is responsible to ensure the existing structure/building is adequate, including, but not limited to, providing sealed engineering and calculations, as-builts, and other information, documentation, or enabling of exploratory work as may be required for ANC's Engineer to adequately design the display system and it's attachment to the base building. ANC assumes base building defined as plywood "backer" or similar condition. | D13: X
B14: Provide mechanical drawings, electrical drawings, shop drawings, and equipment locations for new equipment. | C14: X
B15: Engineering and certification for new equipment attachment design | C15: X
B16: Provide approval of all mechanical drawings, electrical drawings, shop drawings, equipment locations, color renderings, and ad copy layouts for new equipment. | D16: X
B17: Responsible to ensure sufficient structural integrity at points of attachment, including any modifications, additions or alterations to base building construction, as required. | D17: X
B18: Demolition, Removal & Site Cleanup | C18: ANC | D18: Purchaser
B19: Removal of existing equipment and structural components, as required. | C19: NA | F19: Editable
B20: Disposal of existing equipment and structural components, as required. | C20: NA | F20: Editable
B21: Post installation site clean-up. | C21: X
B22: Physical Installation | C22: ANC | D22: Purchaser
B23: Fabricate, deliver, and install support structure and appropriate backing for all displays, including hardware, shims and miscellaneous materials as required. | C23: X
B24: Provide & Install LED components. | C24: X
B25: Provide all required Floor/Site Protection, if required. | D25: X | F25: Editable
B26: Provide camera ready artwork for ad panels, and logos at time of order, if required. | D26: X
B27: Electrical & Data Installation | C27: ANC | D27: Purchaser
B28: Submit electrical engineering drawings | C28: X
B29: Provide (and install, if required) primary power feed within 5' of the display location with sufficient amps for ANC proposed display(s); typically 208v 3-phase. | D29: X | F29: Editable
B30: Provide secondary electrical panels and/or remote power control, if required. | D30: X | F30: Editable
B31: Installation of secondary electrical panels and/or remote power control, if required. Including all conduit, wire, and low voltage conduit & wire as may be required for the remote power control. | D31: X | F31: Editable
B32: Provide & Install all branch circuits necessary to LED display(s) and 120V 1-phase servicing outlets in the vicinity of the display location (if necessary). Exact locations to be coordinated with ANC and electrical contractor. | D32: X | F32: Editable
B33: Furnish signal cables as specified by ANC. | C33: X | F33: Editable
B34: Provide and install signal cable conduit, with pull string, from control location to all Equipment locations/signal termination points, as delineated in the electrical and signal drawings. | D34: X | F34: Editable
B35: Labor to pull signal cable (and remove existing cable), if required. | C35: X | F35: Editable
B36: Terminate signal cable at control system equipment and display equipment, if required. | C36: X | F36: Editable
B37: Mount and install data patch panel in control location and display location, if required. | C37: X | F37: Editable
B38: Provide high speed internet connection to control room equipment. | D38: X
B39: Power outlets on clean dedicated circuit(s) for all control equipment required per electrical engineering within control room location. | D39: X
B40: Control System | C40: ANC | D40: Purchaser
B41: Provide climate controlled control room for all control equipment and processing. Normal operating temperature should be between 65 and 75 degrees Fahrenheit. Normal operating humidity should be less than 80 percent non condensing. | D41: X
...

Sheet Resp Matrix - Pitch Example
A1: Project: | B1: Portland Timbers
A2: Date: | B2: 44802
B4: Administrative | C4: ANC | D4: Purchaser
B5: Provide Payment and Performance Bond. | C5: NA | F5: Editable
B6: All required zoning , building, street or sidewalk closure permits, and associated costs, as required. | C6: NA | F6: Editable
B7: Shipping of all equipment to site. | C7: X
B8: Receive, unload, and inspect all new equipment upon delivery. | C8: X
B9: Provide safe storage of video equipment and control equipment in a safe, dry and secure location until installation, if required. | D9: X
B10: Unobstructed access to equipment and control room throughout installation, until equipment is 100% operational. | D10: X
B11: Engineering & Submittals | C11: ANC | D11: Purchaser
B12: Provide mechanical drawings, electrical drawings, shop drawings, etc as relevant to new equipment. | C12: X
B13: Engineering and certification for new equipment attachment design | C13: NA
B14: Provide approval of all mechanical drawings, electrical drawings, shop drawings, equipment locations, color renderings, and ad copy layouts for new equipment. | D14: X
B15: Responsible to ensure sufficient structural integrity at points of attachment, including any modifications, additions or alterations to base building construction, as required. | C15: NA
B16: Physical Installation and Services | C16: ANC | D16: Purchaser
B17: Provide and Deliver LED Displays and Novastar Display Processors. | C17: X | F17: Editable
B18: Utilize Existing Storage Carts/Racks and all tools and components related to storage. | D18: X | F18: Editable
B19: Column1 | C19: Column2 | D19: Column3
B20: Initial Setup and testing of LED components, including new Novastar Display processing. | C20: X
B21: Provide all required Field/Site Protection, if required. | D21: X | F21: Editable
B22: Post installation site clean-up. Disposal/Use of shipping materials. | D22: X
B23: Electrical & Data Installation | C23: ANC | D23: Purchaser
B24: Submit electrical engineering drawings | C24: X
B25: Provide (and install, if required) primary power feed at the display location with sufficient amps for ANC proposed display(s). | D25: X | F25: Editable
B26: Provide secondary electrical panels and/or remote power control, if required. | D26: X | F26: Editable
B27: Installation of secondary electrical panels, branch circuits and/or remote power control, if required. Including all conduit, wire, and low voltage conduit & wire as may be required for the remote power control. | D27: X | F27: Editable
B28: Furnish signal cables as specified by ANC. | D28: X | F28: Editable
B29: Provide and install signal cable conduit, with pull string, from control location to all Equipment locations/signal termination points, as delineated in the electrical and signal drawings. | D29: X | F29: Editable
B30: Labor to pull signal cable (and remove existing cable), if required. | D30: X | F30: Editable
B31: Terminate signal cable at control system equipment and display equipment, if required. | D31: X | F31: Editable
B32: Mount and install data patch panel in control location and display location, if required. | D32: X | F32: Editable
B33: Provide high speed internet connection to control room equipment. | D33: X
B34: Power outlets on clean dedicated circuit(s) for all control equipment required per electrical engineering within control room location. | D34: X
B35: Control System | C35: ANC | D35: Purchaser
B36: Provide climate controlled control room for all control equipment and processing. Normal operating temperature should be between 65 and 75 degrees Fahrenheit. Normal operating humidity should be less than 80 percent non condensing. | D36: X
B37: Supply static IP address five (5) days prior to installation. | D37: X
B38: Provide and install signal cable conduit, with pull string, from production control location to display for LiveSync control, should remote location be desired. | D38: X | F38: Editable
B39: Labor to pull signal cable for owner supplied control, if required. | D39: X | F39: Editable
B40: Third party application fees as required by the customer, i.e. RSS Feeds, etc. | D40: X
B41: Provide computer(s) for control software. | D41: X
...

Sheet Margin Analysis (CMS Only)
B2: ='Margin Analysis'!B2 -> Project Name: Cleveland Browns - Huntington Bank Field (Budgets)
B3: ='Margin Analysis'!B3 -> 46043
B4: ='Margin Analysis'!B4 -> Revised By: JSR
B6: ='LED Cost Sheet'!A4 -> LED Video Displays | C6: Cost | D6: Selling Price | E6: Margin $ | F6: Margin %
B7: ='LED Cost Sheet'!A7 -> Cleveland Social North Left - LED Display - 4' H x 30' W - 1.2mm (Outdoor) | C7: ='LED Cost Sheet'!V7 -> 145461.52 | D7: ='LED Cost Sheet'!X7 -> 171131.2 | E7: =D7-C7 -> 25669.68 | F7: =E7/D7 -> 0.15
B8: ='Install (Base)'!A20 -> Structural Materials: | C8: ='Install (Base)'!H31 -> 0 | D8: ='Install (Base)'!J31 -> 0 | E8: =D8-C8 -> 0 | F8: =E8/D8 -> #DIV/0!
B9: ='Install (Base)'!A33 -> Structural Labor and LED Installation | C9: ='Install (Base)'!H46 -> 0 | D9: ='Install (Base)'!J46 -> 0 | E9: =D9-C9 -> 0 | F9: =E9/D9 -> #DIV/0!
B10: ='Install (Base)'!A48 -> Electrical and Data - Materials and Subcontracting: | C10: ='Install (Base)'!H57 -> 0 | D10: ='Install (Base)'!J57 -> 0 | E10: =D10-C10 -> 0 | F10: =E10/D10 -> #DIV/0!
B11: ='Install (Base)'!A59 -> Project Management, General Conditions, Travel & Expenses | C11: ='Install (Base)'!H60+'Install (Base)'!H61+'Install (Base)'!H62+'Install (Base)'!H63 -> 0 | D11: ='Install (Base)'!J60+'Install (Base)'!J61+'Install (Base)'!J62+'Install (Base)'!J63 -> 0 | E11: =D11-C11 -> 0 | F11: =E11/D11 -> #DIV/0!
B12: ='Install (Base)'!A69 -> Graphics/Design | C12: ='Install (Base)'!H69 -> 0 | D12: ='Install (Base)'!J69 -> 0 | E12: =D12-C12 -> 0 | F12: 0
B13: ='Install (Base)'!A73 -> Submittals, Engineering, and Permits | C13: ='Install (Base)'!H84 -> 0 | D13: ='Install (Base)'!J84 -> 0 | E13: =D13-C13 -> 0 | F13: =E13/D13 -> #DIV/0!
B14: Content Manangement System Equipment, Installation, and Commissioning
B15: ='Install (Base)'!A101 -> Two Years Parts and Beyond Simple Component Replacement Warranty | C15: ='Install (Base)'!H111 -> 0 | D15: ='Install (Base)'!J111 -> 0 | E15: =D15-C15 -> 0 | F15: 0
C16: =SUM(C7:C15) -> 145461.52 | D16: =SUM(D7:D15) -> 171131.2 | E16: =D16-C16 -> 25669.68 | F16: =E16/D16 -> 0.15
B17: TAX | C17: 0.02 | D17: =D16*C17 -> 3422.624
B18: BOND | C18: 0.0133 | D18: =D16*C18 -> 2276.045
B19: SUB TOTAL (BID FORM) | D19: =SUM(D16:D18) -> 176829.87 | E19: =E16 -> 25669.68 | F19: =E19/D19 -> 0.14516597
B21: Alternates - Add to Cost Above | C21: Cost | D21: Selling Price | E21: Margin $ | F21: Margin %
B22: Alternate #1: Additional Animation Graphics | C22: 5000 | D22: 10000 | E22: =D22-C22 -> 5000 | F22: =E22/D22 -> 0.5
C23: 0 | D23: 0 | E23: =D23-C23 -> 0 | F23: =E23/D23 -> #DIV/0!
C24: 0 | D24: 0 | E24: =D24-C24 -> 0 | F24: =E24/D24 -> #DIV/0!

Sheet Travel (ANC)
D2: vSOFT
B3: Expenses | C3: Week | D3: 1 | E3: TOTALS | H3: MASTER TRAVEL KEY
H4: City | I4: Westchester, NY
B5: City | D5: =I4 -> Westchester, NY | H5: Project | I5: Community College
B6: Project | D6: =I5 -> Community College | H6: Building | I6: Marquee
B7: Building | D7: =$I$6 -> Marquee | H7: Flight / Train Cost | I7: 600
B8: Stage of Job | D8: Install | H8: Car Rental | I8: 125
B9: Number of People | D9: 2 | H9: Taxi / Bus/ Limo | I9: 35
B10: Days of Travel | D10: 3 | H10: Gas | I10: 30
B11: Night of Travel | D11: 4 | H11: Per Diem/Day | I11: 75
